Workbook

Sheet README
A1: PublicLogic Multi-Year Federal Funding Stack
A2: Live-formula model. Yellow cells = editable assumptions (Inputs sheet). Green cells = live totals. Date verified: 2026-06-03. Not legal/accounting advice.
A5: PURPOSE
A6: Show how a PublicLogic client sustains the Discover -> Honor -> Understand -> Improve ->
A7: Build -> Steward -> Continue cycle across 5-10 year budget cycles by BRAIDING federal,
A8: state, tax-credit, and own-source money -- and how PublicLogic's non-contingent fee rides
A9: inside money the client already controls (grant-admin / project soft cost / compliance
A10: infrastructure) under 2 CFR 200.459.
A12: SHEETS
A13: Inputs - every assumption (rates, fees, escalators, award sizes). EDIT HERE.
A14: ExampleA_RuralTown- small/rural MA town, full cycle, braided multi-year stack + own-source handoff.
A15: ExampleB_CapitalDeal - NMTC + Section 45Q + SRF/Brownfields capital/environmental deal w/ compliance tail.
... A30: obligation. This model weights bedrock so the stack survives if the volatile layer is removed.

Sheet Inputs
A1: Inputs -- editable assumptions
A2: Yellow cells feed every formula in the example sheets. Figures are illustrative planning assumptions, not quotes. Verify program terms against current NOFOs before use.
A4: Key | B4: Assumption | C4: Value | D4: Unit | E4: Source / note
A5: infl | B5: Annual escalator (fees & O&M) | C5: 0.03 | D5: /yr | E5: planning assumption
A6: map_fee | B6: PublicLogic Stewardship Map fee (entry) | C6: 35000 | D6: $ | E6: fixed-fee, non-contingent on award (2 CFR 200.459)
A7: narr_fee | B7: Grant-narrative / Understand engagement | C7: 20000 | D7: $ | E7: fixed-fee soft cost
A8: build_pct | B8: PublicLogic compliance-infra on capital | C8: 0.04 | D8: of capital | E8: soft cost / 200.459 prof service; subject to approved budget
A9: ret_fee | B9: Annual stewardship retainer (Steward/Continue) | C9: 24000 | D9: $/yr | E9: own-source operating line once federal ends
A10: deminimis | B10: Default de minimis indirect rate | C10: 0.15 | D10: of MTDC | E10: 2 CFR 200.414(f), 15% effective for awards on/after 10/1/2024
A11: single_aud | B11: Single Audit threshold | C11: 1000000 | D11: $ | E11: 2 CFR 200.501, raised from $750k effective FY beginning on/after 10/1/2024
A12: mtdc_sub | B12: MTDC per-subaward inclusion cap | C12: 50000 | D12: $ | E12: 2 CFR 200.1, raised from $25k in 2024 revision
A13: ccit | B13: A: MA Community Compact IT grant (Y1) | C13: 150000 | D13: $ | E13: FY2026 cap $200k, no match; verified 2026-06-03
A14: cpg | B14: A: MA Community Planning Grant (Y2) | C14: 50000 | D14: $ | E14: Community One Stop; state, low-cost planning entry
A15: massworks | B15: A: MassWorks capital award (Y3) | C15: 1000000 | D15: $ | E15: MA One Stop infrastructure (state bedrock)
A16: cwsrf_a | B16: A: CWSRF loan principal (Y3) | C16: 2000000 | D16: $ | E16: AL 66.458; project loan, 20yr
... A35: gw_award | B35: GW: target award size (if won) | C35: 750000 | D35: $ | E35: illustrative federal capital award being pursued

Sheet ExampleA_RuralTown
A1: Example A -- Small/Rural MA Town: full cycle on a braided multi-year stack
A2: Cycle stage -> source -> cost-treatment route -> dollars by year. Totals are live formulas. Flywheel: the cheap Map produces the diagnosis AND the grant narrative; the narrative opens the capital that funds the Build; the Build budget carries the stewardship cost forward.
A4: Cycle stage | B4: Funding source (layer) | C4: Cost route | D4: Y1 | E4: Y2 | F4: Y3 | G4: Y4 | H4: Y5 | I4: Y6 | J4: Y7 | K4: Row total
A5: Discover | B5: MA Community Compact IT grant [state bedrock] | C5: SOFT | D5: =Inputs!$C$13 | K5: =SUM(D5:J5)
A6: Discover | B6: ^ PublicLogic Stewardship Map (soft cost in the grant) | C6: SOFT | D6: =-Inputs!$C$6 | K6: =SUM(D6:J6)
A7: Honor/Understand | B7: MA Community Planning Grant [state bedrock] | C7: SOFT | E7: =Inputs!$C$14 | K7: =SUM(D7:J7)
A8: Honor/Understand | B8: ^ PublicLogic narrative/Understand (soft cost) | C8: SOFT | E8: =-Inputs!$C$7*(1+Inputs!$C$5)^1 | K8: =SUM(D8:J8)
A9: Improve/Build | B9: MassWorks capital [state bedrock] | C9: SOFT | F9: =Inputs!$C$15 | K9: =SUM(D9:J9)
A10: Improve/Build | B10: CWSRF loan, net of principal forgiveness [federal bedrock] | C10: SOFT | F10: =Inputs!$C$16*(1-Inputs!$C$17) | K10: =SUM(D10:J10)
A11: Improve/Build | B11: ^ PublicLogic compliance-infra (soft cost on capital) | C11: COMPLIANCE | F11: =-(Inputs!$C$15+Inputs!$C$16)*Inputs!$C$8 | K11: =SUM(D11:J11)
A12: Steward | B12: ARPA SLFRF remaining (expend by 12/31/2026) [closing] | C12: ADMIN | D12: =Inputs!$C$18/2 | E12: =Inputs!$C$18/2 | K12: =SUM(D12:J12)
A13: Steward/Continue | B13: Own-source stewardship retainer [own-source bedrock] | C13: ADMIN | G13: =-Inputs!$C$9*(1+Inputs!$C$5)^3 | H13: =-Inputs!$C$9*(1+Inputs!$C$5)^4 | I13: =-Inputs!$C$9*(1+Inputs!$C$5)^5 | J13: =-Inputs!$C$9*(1+Inputs!$C$5)^6 | K13: =SUM(D13:J13)
A14: NET inflow to town (all layers) | D14: =SUM(D5:D13) | E14: =SUM(E5:E13) | F14: =SUM(F5:F13) | G14: =SUM(G5:G13) | H14: =SUM(H5:H13) | I14: =SUM(I5:I13) | J14: =SUM(J5:J13) | K14: =SUM(D14:J14)
A15: CUMULATIVE position | D15: =D14 | E15: =D15+E14 | F15: =E15+F14 | G15: =F15+G14 | H15: =G15+H14 | I15: =H15+I14 | J15: =I15+J14
A17: PublicLogic revenue from this client (Example A)
B18: Map (Discover) | D18: =Inputs!$C$6 | K18: =SUM(D18:J18)
B19: Narrative (Understand) | E19: =Inputs!$C$7*(1+Inputs!$C$5)^1 | K19: =SUM(D19:J19)
B20: Compliance-infra on capital (Build) | F20: =(Inputs!$C$15+Inputs!$C$16)*Inputs!$C$8 | K20: =SUM(D20:J20)
B21: Retainer (Steward/Continue) | G21: =Inputs!$C$9*(1+Inputs!$C$5)^3 | H21: =Inputs!$C$9*(1+Inputs!$C$5)^4 | I21: =Inputs!$C$9*(1+Inputs!$C$5)^5 | J21: =Inputs!$C$9*(1+Inputs!$C$5)^6 | K21: =SUM(D21:J21)
B22: PublicLogic TOTAL (Example A) | D22: =SUM(D18:D21) | E22: =SUM(E18:E21) | F22: =SUM(F18:F21) | G22: =SUM(G18:G21) | H22: =SUM(H18:H21) | I22: =SUM(I18:I21) | J22: =SUM(J18:J21) | K22: =SUM(D22:J22)

Sheet ExampleB_CapitalDeal
A1: Example B -- Capital/Environmental deal: NMTC + Section 45Q + SRF/Brownfields, with compliance tail
A2: Brownfield redevelopment with a carbon-capture component, sponsored by a tax-exempt entity. Tax credits are treated as federal funding. Compliance tail = 7-yr NMTC + 12-yr 45Q -> recurring stewardship.
A4: Component | B4: Mechanism (layer) | C4: Cost route | D4: Y1 | E4: Y2 | F4: Y3 | G4: Y4 | H4: Y5 | I4: Y6 | J4: Y7 | K4: Y8 | L4: Row total
A5: Site cleanup | B5: EPA Brownfields cleanup grant [federal competitive] | C5: SOFT | D5: =Inputs!$C$23 | L5: =SUM(D5:K5)
A6: Site cleanup | B6: ^ non-federal cost share (own-source) | C6: SOFT | D6: =-Inputs!$C$23*Inputs!$C$24 | L6: =SUM(D6:K6)
A7: Water remediation | B7: CWSRF loan (contaminated-site water quality) [federal bedrock] | C7: SOFT | E7: =Inputs!$C$25 | L7: =SUM(D7:K7)
A8: Capital stack | B8: NMTC net subsidy to project [federal bedrock - permanent] | C8: COMPLIANCE | E8: =Inputs!$C$20*Inputs!$C$22 | L8: =SUM(D8:K8)
A9: Clean energy | B9: Section 45Q via elective pay (annual, 12-yr) [statutory bedrock] | C9: COMPLIANCE | D9: =IF(AND(1>=2,1<2+Inputs!$C$28),Inputs!$C$26*Inputs!$C$27*Inputs!$C$29,0) | E9: =IF(AND(2>=2,2<2+Inputs!$C$28),Inputs!$C$26*Inputs!$C$27*Inputs!$C$29,0) | F9: =IF(AND(3>=2,3<2+Inputs!$C$28),Inputs!$C$26*Inputs!$C$27*Inputs!$C$29,0) | G9: =IF(AND(4>=2,4<2+Inputs!$C$28),Inputs!$C$26*Inputs!$C$27*Inputs!$C$29,0) | H9: =IF(AND(5>=2,5<2+Inputs!$C$28),Inputs!$C$26*Inputs!$C$27*Inputs!$C$29,0) | I9: =IF(AND(6>=2,6<2+Inputs!$C$28),Inputs!$C$26*Inputs!$C$27*Inputs!$C$29,0) | J9: =IF(AND(7>=2,7<2+Inputs!$C$28),Inputs!$C$26*Inputs!$C$27*Inputs!$C$29,0) | K9: =IF(AND(8>=2,8<2+Inputs!$C$28),Inputs!$C$26*Inputs!$C$27*Inputs!$C$29,0) | L9: =SUM(D9:K9)
A10: PublicLogic | B10: ^ compliance-infra at financial close (Build) | C10: COMPLIANCE | E10: =-(Inputs!$C$20+Inputs!$C$25)*Inputs!$C$8 | L10: =SUM(D10:K10)
A11: PublicLogic | B11: ^ NMTC 7-yr compliance tail (CDE reporting) | C11: COMPLIANCE | E11: =-Inputs!$C$9*(1+Inputs!$C$5)^1 | F11: =-Inputs!$C$9*(1+Inputs!$C$5)^2 | G11: =-Inputs!$C$9*(1+Inputs!$C$5)^3 | H11: =-Inputs!$C$9*(1+Inputs!$C$5)^4 | I11: =-Inputs!$C$9*(1+Inputs!$C$5)^5 | J11: =-Inputs!$C$9*(1+Inputs!$C$5)^6 | K11: =-Inputs!$C$9*(1+Inputs!$C$5)^7 | L11: =SUM(D11:K11)
A12: NET to deal / sponsor | D12: =SUM(D5:D11) | E12: =SUM(E5:E11) | F12: =SUM(F5:F11) | G12: =SUM(G5:G11) | H12: =SUM(H5:H11) | I12: =SUM(I5:I11) | J12: =SUM(J5:J11) | K12: =SUM(K5:K11) | L12: =SUM(D12:K12)
A13: CUMULATIVE position | D13: =D12 | E13: =D13+E12 | F13: =E13+F12 | G13: =F13+G12 | H13: =G13+H12 | I13: =H13+I12 | J13: =I13+J12 | K13: =J13+K12
A15: PublicLogic revenue from this deal (Example B)
B16: Compliance-infra at close | E16: =(Inputs!$C$20+Inputs!$C$25)*Inputs!$C$8 | L16: =SUM(D16:K16)
B17: NMTC 7-yr compliance tail | E17: =Inputs!$C$9*(1+Inputs!$C$5)^1 | F17: =Inputs!$C$9*(1+Inputs!$C$5)^2 | G17: =Inputs!$C$9*(1+Inputs!$C$5)^3 | H17: =Inputs!$C$9*(1+Inputs!$C$5)^4 | I17: =Inputs!$C$9*(1+Inputs!$C$5)^5 | J17: =Inputs!$C$9*(1+Inputs!$C$5)^6 | K17: =Inputs!$C$9*(1+Inputs!$C$5)^7 | L17: =SUM(D17:K17)
B18: PublicLogic TOTAL (Example B) | D18: =SUM(D16:D17) | E18: =SUM(E16:E17) | F18: =SUM(F16:F17) | G18: =SUM(G16:G17) | H18: =SUM(H16:H17) | I18: =SUM(I16:I17) | J18: =SUM(J16:J17) | K18: =SUM(K16:K17) | L18: =SUM(D18:K18)

Sheet PublicLogic_Revenue
A1: PublicLogic revenue architecture across the stack
A2: Maps the fixed-fee / retainer / compliance-tail structure to allowable cost lines (2 CFR 200.459) and shows the indirect-rate implication. Pulls live totals from the two example sheets.
A4: Revenue line | B4: Cost-treatment route | C4: Allowability basis | D4: Recurring? | E4: Amount
A5: Stewardship Map (entry) | B5: SOFT | C5: Prof. service soft cost; 2 CFR 200.459 | D5: No (per turn) | E5: =Inputs!$C$6
A6: Grant narrative / Understand | B6: SOFT | C6: Soft cost in planning grant; 200.459 | D6: No (per turn) | E6: =Inputs!$C$7*(1+Inputs!$C$5)
A7: Compliance-infra on capital (Ex A+B) | B7: COMPLIANCE | C7: Soft cost on approved capital budget; 200.459 | D7: Per project | E7: =(Inputs!$C$15+Inputs!$C$16+Inputs!$C$20+Inputs!$C$25)*Inputs!$C$8
A8: Stewardship retainer (Ex A own-source) | B8: ADMIN | C8: Own-source operating line; 200.459 once federal ends | D8: Yes (annual) | E8: =Inputs!$C$9
A9: NMTC 7-yr compliance tail (Ex B) | B9: COMPLIANCE | C9: CDE compliance-period monitoring; 200.459 | D9: Yes (7 yrs) | E9: =Inputs!$C$9*7
D10: TOTAL recurring + one-time | E10: =SUM(E5:E9)
A12: INDIRECT-RATE IMPLICATIONS
A13: * With no negotiated rate (NICRA), PublicLogic and its subrecipients may elect the de minimis
A14: rate of 15% of Modified Total Direct Cost (2 CFR 200.414(f); 15% effective for awards on/after 10/1/2024).
A15: * Most PublicLogic fees ride as DIRECT professional-service costs (200.459), not indirect -- so the
A16: de minimis rate mainly affects the client's own overhead recovery, not PublicLogic's fee allowability.
A17: * Fees are FIXED-FEE / RETAINER and NON-CONTINGENT on award; that is what makes them allowable as a
A18: professional-service cost rather than a contingent fee (which 2 CFR 200.459(b) disallows).
A19: * SUBRECIPIENT vs CONTRACTOR (2 CFR 200.331): PublicLogic is a CONTRACTOR -- it provides goods/services
A20: within normal business operations to many purchasers, does not carry programmatic decision-making or
A21: eligibility determination, and is not subject to the federal program's compliance requirements in its
A22: own right. Therefore PublicLogic is procured under 200.317-327 and is NOT itself Single-Audited.
A23: * Single Audit is the CLIENT's obligation only if it expends >= $1,000,000 in federal awards in a year (200.501).
A24: * Not legal/accounting advice -- allowability is subject to the funding source, approved budget, and cost principles.

Sheet GrantWriting_Hours
A1: Grant-writing hours -- an org working with PublicLogic (the work, shown line by line)
A2: Hours x rate = line cost (live formulas). Funding route per line follows the cost principles: writing = proposal cost (2 CFR 200.460, indirect/own-source, non-contingent); post-award = allowable grant-admin on the won award. Not legal/accounting advice.
A4: Phase | B4: Task (the work) | C4: Role | D4: Hours | E4: Rate $/hr | F4: Line cost | G4: Deliverable | H4: Funding route / allowability
A5: 1. Discover/eligibility | B5: Review Stewardship Map; confirm Assistance Listing eligibility | C5: Principal | D5: 4 | E5: =Inputs!$C$30 | F5: =D5*E5 | G5: Eligibility memo | H5: Proposal cost - 2 CFR 200.460: indirect/F&A or org own-source; NON-FederalAward; non-contingent
A6: 1. Discover/eligibility | B6: SAM.gov / UEI registration check; portal setup | C6: Analyst | D6: 3 | E6: =Inputs!$C$31 | F6: =D6*E6 | G6: Registration confirmed | H6: Proposal cost - 2 CFR 200.460: indirect/F&A or org own-source; NON-FederalAward; non-contingent
A7: 2. Narrative | B7: Need statement & problem analysis | C7: Principal | D7: 8 | E7: =Inputs!$C$30 | F7: =D7*E7 | G7: Need statement | H7: Proposal cost - 2 CFR 200.460: indirect/F&A or org own-source; NON-FederalAward; non-contingent
A8: 2. Narrative | B8: Project design & logic model | C8: Principal | D8: 10 | E8: =Inputs!$C$30 | F8: =D8*E8 | G8: Project narrative | H8: Proposal cost - 2 CFR 200.460: indirect/F&A or org own-source; NON-FederalAward; non-contingent
A9: 2. Narrative | B9: Behavioral/organizational sustainability section | C9: Behav/org SME | D9: 6 | E9: =Inputs!$C$32 | F9: =D9*E9 | G9: Sustainability narrative | H9: Proposal cost - 2 CFR 200.460: indirect/F&A or org own-source; NON-FederalAward; non-contingent
A10: 3. Budget | B10: Budget build (cost principles, MTDC, 15% de minimis) | C10: Analyst | D10: 8 | E10: =Inputs!$C$31 | F10: =D10*E10 | G10: SF-424A budget | H10: Proposal cost - 2 CFR 200.460: indirect/F&A or org own-source; NON-FederalAward; non-contingent
A11: 3. Budget | B11: Match/cost-share strategy & budget narrative | C11: Principal | D11: 5 | E11: =Inputs!$C$30 | F11: =D11*E11 | G11: Budget narrative | H11: Proposal cost - 2 CFR 200.460: indirect/F&A or org own-source; NON-FederalAward; non-contingent
A12: 4. Attachments/compliance | B12: SF-424 family, certifications, reps & certs | C12: Analyst | D12: 6 | E12: =Inputs!$C$31 | F12: =D12*E12 | G12: Forms package | H12: Proposal cost - 2 CFR 200.460: indirect/F&A or org own-source; NON-FederalAward; non-contingent
A13: 4. Attachments/compliance | B13: Letters of support, MOUs, env-review coordination | C13: Analyst | D13: 6 | E13: =Inputs!$C$31 | F13: =D13*E13 | G13: Attachments | H13: Proposal cost - 2 CFR 200.460: indirect/F&A or org own-source; NON-FederalAward; non-contingent
A14: 5. Review/submit | B14: Internal review & responsiveness check | C14: Principal | D14: 4 | E14: =Inputs!$C$30 | F14: =D14*E14 | G14: Reviewed package | H14: Proposal cost - 2 CFR 200.460: indirect/F&A or org own-source; NON-FederalAward; non-contingent
A15: 5. Review/submit | B15: Portal submission (grants.gov / state e-grants) | C15: Analyst | D15: 2 | E15: =Inputs!$C$31 | F15: =D15*E15 | G15: Submission receipt | H15: Proposal cost - 2 CFR 200.460: indirect/F&A or org own-source; NON-FederalAward; non-contingent
A16: 6. Post-award (if won) | B16: Award setup, drawdown & subrecipient-monitoring setup | C16: Principal | D16: 8 | E16: =Inputs!$C$30 | F16: =D16*E16 | G16: Grants-mgmt setup | H16: ALLOWABLE on the WON award as grant-administration (200.413 / program admin line)
A17: 6. Post-award (if won) | B17: Compliance calendar & reporting cadence | C17: Analyst | D17: 10 | E17: =Inputs!$C$31 | F17: =D17*E17 | G17: Compliance plan | H17: ALLOWABLE on the WON award as grant-administration (200.413 / program admin line)
B18: WRITING subtotal (proposal cost - own-source / F&A, non-contingent) | D18: =SUM(D5:D15) | F18: =SUM(F5:F15)
B19: POST-AWARD subtotal (allowable grant-admin on the WON award) | D19: =SUM(D16:D17) | F19: =SUM(F16:F17)
B20: ENGAGEMENT TOTAL (time & materials reference) | D20: =D18+D19 | F20: =F18+F19
A22: FIXED-FEE RECONCILIATION (writing block)
B23: Agreed fixed fee for the writing block (non-contingent) | F23: =Inputs!$C$33
B24: Time & materials value of writing hours (from above) | F24: =F18
B25: Fixed-fee variance vs. T&M (org's certainty premium / discount) | F25: =Inputs!$C$33-F18
B26: Writing hours (from above) | F26: =D18
B27: Effective blended rate on the fixed fee | F27: =Inputs!$C$33/D18
A29: WHY NON-CONTINGENT (what PublicLogic does NOT do)
B30: Target award if won (illustrative) | F30: =Inputs!$C$35
B31: Client's expected win probability (planning only) | F31: =Inputs!$C$34
B32: A contingent 'X% of award' fee would be barred by 2 CFR 200.459(b).
B33: PublicLogic charges the FIXED writing fee regardless of outcome -> allowable professional service.
B34: Expected-value of award to the org (context, not a fee basis) | F34: =Inputs!$C$35*Inputs!$C$34
A36: FUNDING-ROUTE NOTES (subject to the funding source, approved budget, and cost principles; not legal/accounting advice)
A37: * 2 CFR 200.460 -- Proposal costs (preparing bids/proposals/applications, successful OR unsuccessful) are normally
A38: treated as INDIRECT (F&A) costs and allocated to current activities; they are NOT directly chargeable to the
A39: federal award being sought. The org pays the writing fee from own-source / unrestricted funds or its F&A pool.
A40: * 2 CFR 200.459(b) -- professional-service costs are allowable; CONTINGENT fees are a factor against allowability.
A41: PublicLogic's writing fee is fixed and NON-CONTINGENT, which is what keeps it an allowable professional service.
A42: * 2 CFR 200.458 -- Pre-award costs are allowable only with prior written approval and only if necessary for the
A43: award; a 90-day-before-award window is typical. Post-award, grant-ADMINISTRATION (a different activity from
A44: writing) is allowable on the won award (200.413 direct admin / program admin line, e.g., CDBG's planning+admin).
...
